{
 "cells": [
  {
   "cell_type": "code",
   "execution_count": 1,
   "id": "f7bfa696",
   "metadata": {},
   "outputs": [
    {
     "name": "stdout",
     "output_type": "stream",
     "text": [
      "Requirement already satisfied: kaggle==1.6.17 in /home/ec2-user/anaconda3/envs/python3/lib/python3.10/site-packages (from -r ./requirements.txt (line 1)) (1.6.17)\n",
      "Requirement already satisfied: matplotlib==3.9.1 in /home/ec2-user/anaconda3/envs/python3/lib/python3.10/site-packages (from -r ./requirements.txt (line 2)) (3.9.1)\n",
      "Requirement already satisfied: pandas==2.2.2 in /home/ec2-user/anaconda3/envs/python3/lib/python3.10/site-packages (from -r ./requirements.txt (line 3)) (2.2.2)\n",
      "Requirement already satisfied: scikit-learn==1.5.1 in /home/ec2-user/anaconda3/envs/python3/lib/python3.10/site-packages (from -r ./requirements.txt (line 4)) (1.5.1)\n",
      "Requirement already satisfied: textblob==0.18.0.post0 in /home/ec2-user/anaconda3/envs/python3/lib/python3.10/site-packages (from -r ./requirements.txt (line 5)) (0.18.0.post0)\n",
      "Requirement already satisfied: six>=1.10 in /home/ec2-user/anaconda3/envs/python3/lib/python3.10/site-packages (from kaggle==1.6.17->-r ./requirements.txt (line 1)) (1.16.0)\n",
      "Requirement already satisfied: certifi>=2023.7.22 in /home/ec2-user/anaconda3/envs/python3/lib/python3.10/site-packages (from kaggle==1.6.17->-r ./requirements.txt (line 1)) (2024.6.2)\n",
      "Requirement already satisfied: python-dateutil in /home/ec2-user/anaconda3/envs/python3/lib/python3.10/site-packages (from kaggle==1.6.17->-r ./requirements.txt (line 1)) (2.9.0)\n",
      "Requirement already satisfied: requests in /home/ec2-user/anaconda3/envs/python3/lib/python3.10/site-packages (from kaggle==1.6.17->-r ./requirements.txt (line 1)) (2.32.3)\n",
      "Requirement already satisfied: tqdm in /home/ec2-user/anaconda3/envs/python3/lib/python3.10/site-packages (from kaggle==1.6.17->-r ./requirements.txt (line 1)) (4.66.4)\n",
      "Requirement already satisfied: python-slugify in /home/ec2-user/anaconda3/envs/python3/lib/python3.10/site-packages (from kaggle==1.6.17->-r ./requirements.txt (line 1)) (8.0.4)\n",
      "Requirement already satisfied: urllib3 in /home/ec2-user/anaconda3/envs/python3/lib/python3.10/site-packages (from kaggle==1.6.17->-r ./requirements.txt (line 1)) (2.2.1)\n",
      "Requirement already satisfied: bleach in /home/ec2-user/anaconda3/envs/python3/lib/python3.10/site-packages (from kaggle==1.6.17->-r ./requirements.txt (line 1)) (6.1.0)\n",
      "Requirement already satisfied: contourpy>=1.0.1 in /home/ec2-user/anaconda3/envs/python3/lib/python3.10/site-packages (from matplotlib==3.9.1->-r ./requirements.txt (line 2)) (1.2.1)\n",
      "Requirement already satisfied: cycler>=0.10 in /home/ec2-user/anaconda3/envs/python3/lib/python3.10/site-packages (from matplotlib==3.9.1->-r ./requirements.txt (line 2)) (0.12.1)\n",
      "Requirement already satisfied: fonttools>=4.22.0 in /home/ec2-user/anaconda3/envs/python3/lib/python3.10/site-packages (from matplotlib==3.9.1->-r ./requirements.txt (line 2)) (4.53.0)\n",
      "Requirement already satisfied: kiwisolver>=1.3.1 in /home/ec2-user/anaconda3/envs/python3/lib/python3.10/site-packages (from matplotlib==3.9.1->-r ./requirements.txt (line 2)) (1.4.5)\n",
      "Requirement already satisfied: numpy>=1.23 in /home/ec2-user/anaconda3/envs/python3/lib/python3.10/site-packages (from matplotlib==3.9.1->-r ./requirements.txt (line 2)) (2.0.1)\n",
      "Requirement already satisfied: packaging>=20.0 in /home/ec2-user/anaconda3/envs/python3/lib/python3.10/site-packages (from matplotlib==3.9.1->-r ./requirements.txt (line 2)) (21.3)\n",
      "Requirement already satisfied: pillow>=8 in /home/ec2-user/anaconda3/envs/python3/lib/python3.10/site-packages (from matplotlib==3.9.1->-r ./requirements.txt (line 2)) (10.3.0)\n",
      "Requirement already satisfied: pyparsing>=2.3.1 in /home/ec2-user/anaconda3/envs/python3/lib/python3.10/site-packages (from matplotlib==3.9.1->-r ./requirements.txt (line 2)) (3.1.2)\n",
      "Requirement already satisfied: pytz>=2020.1 in /home/ec2-user/anaconda3/envs/python3/lib/python3.10/site-packages (from pandas==2.2.2->-r ./requirements.txt (line 3)) (2024.1)\n",
      "Requirement already satisfied: tzdata>=2022.7 in /home/ec2-user/anaconda3/envs/python3/lib/python3.10/site-packages (from pandas==2.2.2->-r ./requirements.txt (line 3)) (2024.1)\n",
      "Requirement already satisfied: scipy>=1.6.0 in /home/ec2-user/anaconda3/envs/python3/lib/python3.10/site-packages (from scikit-learn==1.5.1->-r ./requirements.txt (line 4)) (1.13.1)\n",
      "Requirement already satisfied: joblib>=1.2.0 in /home/ec2-user/anaconda3/envs/python3/lib/python3.10/site-packages (from scikit-learn==1.5.1->-r ./requirements.txt (line 4)) (1.4.2)\n",
      "Requirement already satisfied: threadpoolctl>=3.1.0 in /home/ec2-user/anaconda3/envs/python3/lib/python3.10/site-packages (from scikit-learn==1.5.1->-r ./requirements.txt (line 4)) (3.5.0)\n",
      "Requirement already satisfied: nltk>=3.8 in /home/ec2-user/anaconda3/envs/python3/lib/python3.10/site-packages (from textblob==0.18.0.post0->-r ./requirements.txt (line 5)) (3.8.1)\n",
      "Requirement already satisfied: click in /home/ec2-user/anaconda3/envs/python3/lib/python3.10/site-packages (from nltk>=3.8->textblob==0.18.0.post0->-r ./requirements.txt (line 5)) (8.1.7)\n",
      "Requirement already satisfied: regex>=2021.8.3 in /home/ec2-user/anaconda3/envs/python3/lib/python3.10/site-packages (from nltk>=3.8->textblob==0.18.0.post0->-r ./requirements.txt (line 5)) (2024.5.15)\n",
      "Requirement already satisfied: webencodings in /home/ec2-user/anaconda3/envs/python3/lib/python3.10/site-packages (from bleach->kaggle==1.6.17->-r ./requirements.txt (line 1)) (0.5.1)\n",
      "Requirement already satisfied: text-unidecode>=1.3 in /home/ec2-user/anaconda3/envs/python3/lib/python3.10/site-packages (from python-slugify->kaggle==1.6.17->-r ./requirements.txt (line 1)) (1.3)\n",
      "Requirement already satisfied: charset-normalizer<4,>=2 in /home/ec2-user/anaconda3/envs/python3/lib/python3.10/site-packages (from requests->kaggle==1.6.17->-r ./requirements.txt (line 1)) (3.3.2)\n",
      "Requirement already satisfied: idna<4,>=2.5 in /home/ec2-user/anaconda3/envs/python3/lib/python3.10/site-packages (from requests->kaggle==1.6.17->-r ./requirements.txt (line 1)) (3.7)\n",
      "Note: you may need to restart the kernel to use updated packages.\n"
     ]
    }
   ],
   "source": [
    "pip install -r ./requirements.txt"
   ]
  },
  {
   "cell_type": "code",
   "execution_count": 2,
   "id": "acd11a02",
   "metadata": {},
   "outputs": [
    {
     "name": "stderr",
     "output_type": "stream",
     "text": [
      "\n",
      "A module that was compiled using NumPy 1.x cannot be run in\n",
      "NumPy 2.0.1 as it may crash. To support both 1.x and 2.x\n",
      "versions of NumPy, modules must be compiled with NumPy 2.0.\n",
      "Some module may need to rebuild instead e.g. with 'pybind11>=2.12'.\n",
      "\n",
      "If you are a user of the module, the easiest solution will be to\n",
      "downgrade to 'numpy<2' or try to upgrade the affected module.\n",
      "We expect that some modules will need time to support NumPy 2.\n",
      "\n",
      "Traceback (most recent call last):  File \"/home/ec2-user/anaconda3/envs/python3/lib/python3.10/runpy.py\", line 196, in _run_module_as_main\n",
      "    return _run_code(code, main_globals, None,\n",
      "  File \"/home/ec2-user/anaconda3/envs/python3/lib/python3.10/runpy.py\", line 86, in _run_code\n",
      "    exec(code, run_globals)\n",
      "  File \"/home/ec2-user/anaconda3/envs/python3/lib/python3.10/site-packages/ipykernel_launcher.py\", line 18, in <module>\n",
      "    app.launch_new_instance()\n",
      "  File \"/home/ec2-user/anaconda3/envs/python3/lib/python3.10/site-packages/traitlets/config/application.py\", line 1075, in launch_instance\n",
      "    app.start()\n",
      "  File \"/home/ec2-user/anaconda3/envs/python3/lib/python3.10/site-packages/ipykernel/kernelapp.py\", line 739, in start\n",
      "    self.io_loop.start()\n",
      "  File \"/home/ec2-user/anaconda3/envs/python3/lib/python3.10/site-packages/tornado/platform/asyncio.py\", line 205, in start\n",
      "    self.asyncio_loop.run_forever()\n",
      "  File \"/home/ec2-user/anaconda3/envs/python3/lib/python3.10/asyncio/base_events.py\", line 603, in run_forever\n",
      "    self._run_once()\n",
      "  File \"/home/ec2-user/anaconda3/envs/python3/lib/python3.10/asyncio/base_events.py\", line 1909, in _run_once\n",
      "    handle._run()\n",
      "  File \"/home/ec2-user/anaconda3/envs/python3/lib/python3.10/asyncio/events.py\", line 80, in _run\n",
      "    self._context.run(self._callback, *self._args)\n",
      "  File \"/home/ec2-user/anaconda3/envs/python3/lib/python3.10/site-packages/ipykernel/kernelbase.py\", line 545, in dispatch_queue\n",
      "    await self.process_one()\n",
      "  File \"/home/ec2-user/anaconda3/envs/python3/lib/python3.10/site-packages/ipykernel/kernelbase.py\", line 534, in process_one\n",
      "    await dispatch(*args)\n",
      "  File \"/home/ec2-user/anaconda3/envs/python3/lib/python3.10/site-packages/ipykernel/kernelbase.py\", line 437, in dispatch_shell\n",
      "    await result\n",
      "  File \"/home/ec2-user/anaconda3/envs/python3/lib/python3.10/site-packages/ipykernel/ipkernel.py\", line 359, in execute_request\n",
      "    await super().execute_request(stream, ident, parent)\n",
      "  File \"/home/ec2-user/anaconda3/envs/python3/lib/python3.10/site-packages/ipykernel/kernelbase.py\", line 778, in execute_request\n",
      "    reply_content = await reply_content\n",
      "  File \"/home/ec2-user/anaconda3/envs/python3/lib/python3.10/site-packages/ipykernel/ipkernel.py\", line 446, in do_execute\n",
      "    res = shell.run_cell(\n",
      "  File \"/home/ec2-user/anaconda3/envs/python3/lib/python3.10/site-packages/ipykernel/zmqshell.py\", line 549, in run_cell\n",
      "    return super().run_cell(*args, **kwargs)\n",
      "  File \"/home/ec2-user/anaconda3/envs/python3/lib/python3.10/site-packages/IPython/core/interactiveshell.py\", line 3075, in run_cell\n",
      "    result = self._run_cell(\n",
      "  File \"/home/ec2-user/anaconda3/envs/python3/lib/python3.10/site-packages/IPython/core/interactiveshell.py\", line 3130, in _run_cell\n",
      "    result = runner(coro)\n",
      "  File \"/home/ec2-user/anaconda3/envs/python3/lib/python3.10/site-packages/IPython/core/async_helpers.py\", line 129, in _pseudo_sync_runner\n",
      "    coro.send(None)\n",
      "  File \"/home/ec2-user/anaconda3/envs/python3/lib/python3.10/site-packages/IPython/core/interactiveshell.py\", line 3334, in run_cell_async\n",
      "    has_raised = await self.run_ast_nodes(code_ast.body, cell_name,\n",
      "  File \"/home/ec2-user/anaconda3/envs/python3/lib/python3.10/site-packages/IPython/core/interactiveshell.py\", line 3517, in run_ast_nodes\n",
      "    if await self.run_code(code, result, async_=asy):\n",
      "  File \"/home/ec2-user/anaconda3/envs/python3/lib/python3.10/site-packages/IPython/core/interactiveshell.py\", line 3577, in run_code\n",
      "    exec(code_obj, self.user_global_ns, self.user_ns)\n",
      "  File \"/tmp/ipykernel_28245/914782578.py\", line 5, in <module>\n",
      "    import pandas as pd\n",
      "  File \"/home/ec2-user/anaconda3/envs/python3/lib/python3.10/site-packages/pandas/__init__.py\", line 26, in <module>\n",
      "    from pandas.compat import (\n",
      "  File \"/home/ec2-user/anaconda3/envs/python3/lib/python3.10/site-packages/pandas/compat/__init__.py\", line 27, in <module>\n",
      "    from pandas.compat.pyarrow import (\n",
      "  File \"/home/ec2-user/anaconda3/envs/python3/lib/python3.10/site-packages/pandas/compat/pyarrow.py\", line 8, in <module>\n",
      "    import pyarrow as pa\n",
      "  File \"/home/ec2-user/anaconda3/envs/python3/lib/python3.10/site-packages/pyarrow/__init__.py\", line 65, in <module>\n",
      "    import pyarrow.lib as _lib\n"
     ]
    },
    {
     "ename": "AttributeError",
     "evalue": "_ARRAY_API not found",
     "output_type": "error",
     "traceback": [
      "\u001b[0;31m---------------------------------------------------------------------------\u001b[0m",
      "\u001b[0;31mAttributeError\u001b[0m                            Traceback (most recent call last)",
      "\u001b[0;31mAttributeError\u001b[0m: _ARRAY_API not found"
     ]
    },
    {
     "name": "stderr",
     "output_type": "stream",
     "text": [
      "\n",
      "A module that was compiled using NumPy 1.x cannot be run in\n",
      "NumPy 2.0.1 as it may crash. To support both 1.x and 2.x\n",
      "versions of NumPy, modules must be compiled with NumPy 2.0.\n",
      "Some module may need to rebuild instead e.g. with 'pybind11>=2.12'.\n",
      "\n",
      "If you are a user of the module, the easiest solution will be to\n",
      "downgrade to 'numpy<2' or try to upgrade the affected module.\n",
      "We expect that some modules will need time to support NumPy 2.\n",
      "\n",
      "Traceback (most recent call last):  File \"/home/ec2-user/anaconda3/envs/python3/lib/python3.10/runpy.py\", line 196, in _run_module_as_main\n",
      "    return _run_code(code, main_globals, None,\n",
      "  File \"/home/ec2-user/anaconda3/envs/python3/lib/python3.10/runpy.py\", line 86, in _run_code\n",
      "    exec(code, run_globals)\n",
      "  File \"/home/ec2-user/anaconda3/envs/python3/lib/python3.10/site-packages/ipykernel_launcher.py\", line 18, in <module>\n",
      "    app.launch_new_instance()\n",
      "  File \"/home/ec2-user/anaconda3/envs/python3/lib/python3.10/site-packages/traitlets/config/application.py\", line 1075, in launch_instance\n",
      "    app.start()\n",
      "  File \"/home/ec2-user/anaconda3/envs/python3/lib/python3.10/site-packages/ipykernel/kernelapp.py\", line 739, in start\n",
      "    self.io_loop.start()\n",
      "  File \"/home/ec2-user/anaconda3/envs/python3/lib/python3.10/site-packages/tornado/platform/asyncio.py\", line 205, in start\n",
      "    self.asyncio_loop.run_forever()\n",
      "  File \"/home/ec2-user/anaconda3/envs/python3/lib/python3.10/asyncio/base_events.py\", line 603, in run_forever\n",
      "    self._run_once()\n",
      "  File \"/home/ec2-user/anaconda3/envs/python3/lib/python3.10/asyncio/base_events.py\", line 1909, in _run_once\n",
      "    handle._run()\n",
      "  File \"/home/ec2-user/anaconda3/envs/python3/lib/python3.10/asyncio/events.py\", line 80, in _run\n",
      "    self._context.run(self._callback, *self._args)\n",
      "  File \"/home/ec2-user/anaconda3/envs/python3/lib/python3.10/site-packages/ipykernel/kernelbase.py\", line 545, in dispatch_queue\n",
      "    await self.process_one()\n",
      "  File \"/home/ec2-user/anaconda3/envs/python3/lib/python3.10/site-packages/ipykernel/kernelbase.py\", line 534, in process_one\n",
      "    await dispatch(*args)\n",
      "  File \"/home/ec2-user/anaconda3/envs/python3/lib/python3.10/site-packages/ipykernel/kernelbase.py\", line 437, in dispatch_shell\n",
      "    await result\n",
      "  File \"/home/ec2-user/anaconda3/envs/python3/lib/python3.10/site-packages/ipykernel/ipkernel.py\", line 359, in execute_request\n",
      "    await super().execute_request(stream, ident, parent)\n",
      "  File \"/home/ec2-user/anaconda3/envs/python3/lib/python3.10/site-packages/ipykernel/kernelbase.py\", line 778, in execute_request\n",
      "    reply_content = await reply_content\n",
      "  File \"/home/ec2-user/anaconda3/envs/python3/lib/python3.10/site-packages/ipykernel/ipkernel.py\", line 446, in do_execute\n",
      "    res = shell.run_cell(\n",
      "  File \"/home/ec2-user/anaconda3/envs/python3/lib/python3.10/site-packages/ipykernel/zmqshell.py\", line 549, in run_cell\n",
      "    return super().run_cell(*args, **kwargs)\n",
      "  File \"/home/ec2-user/anaconda3/envs/python3/lib/python3.10/site-packages/IPython/core/interactiveshell.py\", line 3075, in run_cell\n",
      "    result = self._run_cell(\n",
      "  File \"/home/ec2-user/anaconda3/envs/python3/lib/python3.10/site-packages/IPython/core/interactiveshell.py\", line 3130, in _run_cell\n",
      "    result = runner(coro)\n",
      "  File \"/home/ec2-user/anaconda3/envs/python3/lib/python3.10/site-packages/IPython/core/async_helpers.py\", line 129, in _pseudo_sync_runner\n",
      "    coro.send(None)\n",
      "  File \"/home/ec2-user/anaconda3/envs/python3/lib/python3.10/site-packages/IPython/core/interactiveshell.py\", line 3334, in run_cell_async\n",
      "    has_raised = await self.run_ast_nodes(code_ast.body, cell_name,\n",
      "  File \"/home/ec2-user/anaconda3/envs/python3/lib/python3.10/site-packages/IPython/core/interactiveshell.py\", line 3517, in run_ast_nodes\n",
      "    if await self.run_code(code, result, async_=asy):\n",
      "  File \"/home/ec2-user/anaconda3/envs/python3/lib/python3.10/site-packages/IPython/core/interactiveshell.py\", line 3577, in run_code\n",
      "    exec(code_obj, self.user_global_ns, self.user_ns)\n",
      "  File \"/tmp/ipykernel_28245/914782578.py\", line 5, in <module>\n",
      "    import pandas as pd\n",
      "  File \"/home/ec2-user/anaconda3/envs/python3/lib/python3.10/site-packages/pandas/__init__.py\", line 49, in <module>\n",
      "    from pandas.core.api import (\n",
      "  File \"/home/ec2-user/anaconda3/envs/python3/lib/python3.10/site-packages/pandas/core/api.py\", line 9, in <module>\n",
      "    from pandas.core.dtypes.dtypes import (\n",
      "  File \"/home/ec2-user/anaconda3/envs/python3/lib/python3.10/site-packages/pandas/core/dtypes/dtypes.py\", line 24, in <module>\n",
      "    from pandas._libs import (\n",
      "  File \"/home/ec2-user/anaconda3/envs/python3/lib/python3.10/site-packages/pyarrow/__init__.py\", line 65, in <module>\n",
      "    import pyarrow.lib as _lib\n"
     ]
    },
    {
     "ename": "AttributeError",
     "evalue": "_ARRAY_API not found",
     "output_type": "error",
     "traceback": [
      "\u001b[0;31m---------------------------------------------------------------------------\u001b[0m",
      "\u001b[0;31mAttributeError\u001b[0m                            Traceback (most recent call last)",
      "\u001b[0;31mAttributeError\u001b[0m: _ARRAY_API not found"
     ]
    },
    {
     "name": "stderr",
     "output_type": "stream",
     "text": [
      "\n",
      "A module that was compiled using NumPy 1.x cannot be run in\n",
      "NumPy 2.0.1 as it may crash. To support both 1.x and 2.x\n",
      "versions of NumPy, modules must be compiled with NumPy 2.0.\n",
      "Some module may need to rebuild instead e.g. with 'pybind11>=2.12'.\n",
      "\n",
      "If you are a user of the module, the easiest solution will be to\n",
      "downgrade to 'numpy<2' or try to upgrade the affected module.\n",
      "We expect that some modules will need time to support NumPy 2.\n",
      "\n",
      "Traceback (most recent call last):  File \"/home/ec2-user/anaconda3/envs/python3/lib/python3.10/runpy.py\", line 196, in _run_module_as_main\n",
      "    return _run_code(code, main_globals, None,\n",
      "  File \"/home/ec2-user/anaconda3/envs/python3/lib/python3.10/runpy.py\", line 86, in _run_code\n",
      "    exec(code, run_globals)\n",
      "  File \"/home/ec2-user/anaconda3/envs/python3/lib/python3.10/site-packages/ipykernel_launcher.py\", line 18, in <module>\n",
      "    app.launch_new_instance()\n",
      "  File \"/home/ec2-user/anaconda3/envs/python3/lib/python3.10/site-packages/traitlets/config/application.py\", line 1075, in launch_instance\n",
      "    app.start()\n",
      "  File \"/home/ec2-user/anaconda3/envs/python3/lib/python3.10/site-packages/ipykernel/kernelapp.py\", line 739, in start\n",
      "    self.io_loop.start()\n",
      "  File \"/home/ec2-user/anaconda3/envs/python3/lib/python3.10/site-packages/tornado/platform/asyncio.py\", line 205, in start\n",
      "    self.asyncio_loop.run_forever()\n",
      "  File \"/home/ec2-user/anaconda3/envs/python3/lib/python3.10/asyncio/base_events.py\", line 603, in run_forever\n",
      "    self._run_once()\n",
      "  File \"/home/ec2-user/anaconda3/envs/python3/lib/python3.10/asyncio/base_events.py\", line 1909, in _run_once\n",
      "    handle._run()\n",
      "  File \"/home/ec2-user/anaconda3/envs/python3/lib/python3.10/asyncio/events.py\", line 80, in _run\n",
      "    self._context.run(self._callback, *self._args)\n",
      "  File \"/home/ec2-user/anaconda3/envs/python3/lib/python3.10/site-packages/ipykernel/kernelbase.py\", line 545, in dispatch_queue\n",
      "    await self.process_one()\n",
      "  File \"/home/ec2-user/anaconda3/envs/python3/lib/python3.10/site-packages/ipykernel/kernelbase.py\", line 534, in process_one\n",
      "    await dispatch(*args)\n",
      "  File \"/home/ec2-user/anaconda3/envs/python3/lib/python3.10/site-packages/ipykernel/kernelbase.py\", line 437, in dispatch_shell\n",
      "    await result\n",
      "  File \"/home/ec2-user/anaconda3/envs/python3/lib/python3.10/site-packages/ipykernel/ipkernel.py\", line 359, in execute_request\n",
      "    await super().execute_request(stream, ident, parent)\n",
      "  File \"/home/ec2-user/anaconda3/envs/python3/lib/python3.10/site-packages/ipykernel/kernelbase.py\", line 778, in execute_request\n",
      "    reply_content = await reply_content\n",
      "  File \"/home/ec2-user/anaconda3/envs/python3/lib/python3.10/site-packages/ipykernel/ipkernel.py\", line 446, in do_execute\n",
      "    res = shell.run_cell(\n",
      "  File \"/home/ec2-user/anaconda3/envs/python3/lib/python3.10/site-packages/ipykernel/zmqshell.py\", line 549, in run_cell\n",
      "    return super().run_cell(*args, **kwargs)\n",
      "  File \"/home/ec2-user/anaconda3/envs/python3/lib/python3.10/site-packages/IPython/core/interactiveshell.py\", line 3075, in run_cell\n",
      "    result = self._run_cell(\n",
      "  File \"/home/ec2-user/anaconda3/envs/python3/lib/python3.10/site-packages/IPython/core/interactiveshell.py\", line 3130, in _run_cell\n",
      "    result = runner(coro)\n",
      "  File \"/home/ec2-user/anaconda3/envs/python3/lib/python3.10/site-packages/IPython/core/async_helpers.py\", line 129, in _pseudo_sync_runner\n",
      "    coro.send(None)\n",
      "  File \"/home/ec2-user/anaconda3/envs/python3/lib/python3.10/site-packages/IPython/core/interactiveshell.py\", line 3334, in run_cell_async\n",
      "    has_raised = await self.run_ast_nodes(code_ast.body, cell_name,\n",
      "  File \"/home/ec2-user/anaconda3/envs/python3/lib/python3.10/site-packages/IPython/core/interactiveshell.py\", line 3517, in run_ast_nodes\n",
      "    if await self.run_code(code, result, async_=asy):\n",
      "  File \"/home/ec2-user/anaconda3/envs/python3/lib/python3.10/site-packages/IPython/core/interactiveshell.py\", line 3577, in run_code\n",
      "    exec(code_obj, self.user_global_ns, self.user_ns)\n",
      "  File \"/tmp/ipykernel_28245/914782578.py\", line 5, in <module>\n",
      "    import pandas as pd\n",
      "  File \"/home/ec2-user/anaconda3/envs/python3/lib/python3.10/site-packages/pandas/__init__.py\", line 49, in <module>\n",
      "    from pandas.core.api import (\n",
      "  File \"/home/ec2-user/anaconda3/envs/python3/lib/python3.10/site-packages/pandas/core/api.py\", line 28, in <module>\n",
      "    from pandas.core.arrays import Categorical\n",
      "  File \"/home/ec2-user/anaconda3/envs/python3/lib/python3.10/site-packages/pandas/core/arrays/__init__.py\", line 1, in <module>\n",
      "    from pandas.core.arrays.arrow import ArrowExtensionArray\n",
      "  File \"/home/ec2-user/anaconda3/envs/python3/lib/python3.10/site-packages/pandas/core/arrays/arrow/__init__.py\", line 5, in <module>\n",
      "    from pandas.core.arrays.arrow.array import ArrowExtensionArray\n",
      "  File \"/home/ec2-user/anaconda3/envs/python3/lib/python3.10/site-packages/pandas/core/arrays/arrow/array.py\", line 64, in <module>\n",
      "    from pandas.core.arrays.masked import BaseMaskedArray\n",
      "  File \"/home/ec2-user/anaconda3/envs/python3/lib/python3.10/site-packages/pandas/core/arrays/masked.py\", line 60, in <module>\n",
      "    from pandas.core import (\n",
      "  File \"/home/ec2-user/anaconda3/envs/python3/lib/python3.10/site-packages/pandas/core/nanops.py\", line 52, in <module>\n",
      "    bn = import_optional_dependency(\"bottleneck\", errors=\"warn\")\n",
      "  File \"/home/ec2-user/anaconda3/envs/python3/lib/python3.10/site-packages/pandas/compat/_optional.py\", line 135, in import_optional_dependency\n",
      "    module = importlib.import_module(name)\n",
      "  File \"/home/ec2-user/anaconda3/envs/python3/lib/python3.10/importlib/__init__.py\", line 126, in import_module\n",
      "    return _bootstrap._gcd_import(name[level:], package, level)\n",
      "  File \"/home/ec2-user/anaconda3/envs/python3/lib/python3.10/site-packages/bottleneck/__init__.py\", line 7, in <module>\n",
      "    from .move import (move_argmax, move_argmin, move_max, move_mean, move_median,\n"
     ]
    },
    {
     "ename": "AttributeError",
     "evalue": "_ARRAY_API not found",
     "output_type": "error",
     "traceback": [
      "\u001b[0;31m---------------------------------------------------------------------------\u001b[0m",
      "\u001b[0;31mAttributeError\u001b[0m                            Traceback (most recent call last)",
      "\u001b[0;31mAttributeError\u001b[0m: _ARRAY_API not found"
     ]
    }
   ],
   "source": [
    "import time\n",
    "\n",
    "import matplotlib.pyplot as plt\n",
    "\n",
    "import pandas as pd\n",
    "\n",
    "from sklearn.metrics import mean_squared_error\n",
    "from sklearn.model_selection import GridSearchCV, train_test_split\n",
    "from sklearn.neighbors import KNeighborsRegressor\n",
    "\n",
    "merged_book_attributes_gold = './data/gold/merged_book_attributes.csv'"
   ]
  },
  {
   "cell_type": "code",
   "execution_count": 3,
   "id": "3648d482",
   "metadata": {},
   "outputs": [],
   "source": [
    "merged_book_attributes = pd.read_csv(merged_book_attributes_gold)"
   ]
  },
  {
   "cell_type": "code",
   "execution_count": 4,
   "id": "59dd5838",
   "metadata": {},
   "outputs": [],
   "source": [
    "X_train, X_test, y_train, y_test = train_test_split(merged_book_attributes[['price', 'full_review_sentiment_score', 'review_summary_sentiment_score', 'books_average_rating']], merged_book_attributes[['rating']], test_size=0.2, random_state=42)"
   ]
  },
  {
   "cell_type": "code",
   "execution_count": null,
   "id": "f18ea219",
   "metadata": {},
   "outputs": [],
   "source": [
    "knn_regressor = KNeighborsRegressor()\n",
    "param_grid = {'n_neighbors': range(1, 17), 'weights': ['uniform', 'distance']}\n",
    "best_knn_regressor = GridSearchCV(knn_regressor, param_grid, cv=5, scoring='r2')\n",
    "\n",
    "start = time.time()\n",
    "best_knn_regressor.fit(X_train, y_train)\n",
    "stop = time.time()\n",
    "knn_regressor_training_time = round(stop - start, 2)\n",
    "print(f\"K-nearest neighbors training time: {knn_regressor_training_time}s\")\n",
    "\n",
    "print(\"Best parameters:\", best_knn_regressor.best_params_)\n",
    "print(\"Best r2 score:\", best_knn_regressor.best_score_)"
   ]
  },
  {
   "cell_type": "code",
   "execution_count": null,
   "id": "fdd268fe",
   "metadata": {},
   "outputs": [],
   "source": [
    "print(f\"r2 score on test data: {best_knn_regressor.score(X_test, y_test)}\")"
   ]
  },
  {
   "cell_type": "code",
   "execution_count": null,
   "id": "c3a6a592",
   "metadata": {},
   "outputs": [],
   "source": [
    "knn_models = []\n",
    "for k in range(1, 17):\n",
    "    knn_regressor = KNeighborsRegressor(n_neighbors=k)\n",
    "    knn_models.append(knn_regressor)"
   ]
  },
  {
   "cell_type": "code",
   "execution_count": null,
   "id": "976e8e93",
   "metadata": {},
   "outputs": [],
   "source": [
    "mse_values = []\n",
    "for index, knn_regressor in enumerate(knn_models):\n",
    "    knn_regressor.fit(X_train, y_train)\n",
    "    y_pred = knn_regressor.predict(X_test)\n",
    "    mse = mean_squared_error(y_test, y_pred)\n",
    "    mse_values.append(mse)"
   ]
  },
  {
   "cell_type": "code",
   "execution_count": null,
   "id": "1d566c04",
   "metadata": {},
   "outputs": [],
   "source": [
    "plt.plot([i for i in range(1, len(knn_models) + 1)], mse_values)\n",
    "plt.xlabel('Number of Neighbors (k)')\n",
    "plt.ylabel('Mean Squared Error (MSE)')\n",
    "plt.title('Elbow plot for k-nearest neighbors regression model')\n",
    "plt.show()"
   ]
  }
 ],
 "metadata": {
  "kernelspec": {
   "display_name": "conda_python3",
   "language": "python",
   "name": "conda_python3"
  },
  "language_info": {
   "codemirror_mode": {
    "name": "ipython",
    "version": 3
   },
   "file_extension": ".py",
   "mimetype": "text/x-python",
   "name": "python",
   "nbconvert_exporter": "python",
   "pygments_lexer": "ipython3",
   "version": "3.10.14"
  }
 },
 "nbformat": 4,
 "nbformat_minor": 5
}
